Workbook

Sheet Summary
A1: cabang | B1: Omset Jan25 | C1: Omset Mei26 | D1: Growth | E1: latitude_cabang | F1: longitude_cabang | G1: Persen Growth | H1: Kategori | I1: lama_buka_bulan
A2: GGP031 | B2: 2304800000 | C2: 3322750000 | D2: =C2-B2 -> 1017950000 | E2: =VLOOKUP(A2,KOORDINAT!A:B,2,0) -> -6.150095 | F2: =VLOOKUP(A2,KOORDINAT!A:C,3,0) -> 106.81736 | G2: =D2/B2 -> 0.44166522 | H2: =IFS(G2 > 35%, "Sangat Baik", G2 >= 0%, "Baik", G2 >= -35%, "Kurang Baik", G2 < -35%, "Jelek") -> Sangat Baik | I2: 104
A3: MGW001 | B3: 1970100000 | C3: 3302900000 | D3: =C3-B3 -> 1332800000 | E3: =VLOOKUP(A3,KOORDINAT!A:B,2,0) -> -8.741153 | F3: =VLOOKUP(A3,KOORDINAT!A:C,3,0) -> 115.17865 | G3: =D3/B3 -> 0.67651388 | H3: =IFS(G3 > 35%, "Sangat Baik", G3 >= 0%, "Baik", G3 >= -35%, "Kurang Baik", G3 < -35%, "Jelek") -> Sangat Baik | I3: 104
A4: DPR001 | B4: 2672300000 | C4: 3207300000 | D4: =C4-B4 -> 535000000 | E4: =VLOOKUP(A4,KOORDINAT!A:B,2,0) -> -8.68093 | F4: =VLOOKUP(A4,KOORDINAT!A:C,3,0) -> 115.20171 | G4: =D4/B4 -> 0.20020207 | H4: =IFS(G4 > 35%, "Sangat Baik", G4 >= 0%, "Baik", G4 >= -35%, "Kurang Baik", G4 < -35%, "Jelek") -> Baik | I4: 104
A5: GGP033 | B5: 2025350000 | C5: 2862550000 | D5: =C5-B5 -> 837200000 | E5: =VLOOKUP(A5,KOORDINAT!A:B,2,0) -> -6.16589 | F5: =VLOOKUP(A5,KOORDINAT!A:C,3,0) -> 106.79969 | G5: =D5/B5 -> 0.41336065 | H5: =IFS(G5 > 35%, "Sangat Baik", G5 >= 0%, "Baik", G5 >= -35%, "Kurang Baik", G5 < -35%, "Jelek") -> Sangat Baik | I5: 105
A6: KYB003 | B6: 2273900000 | C6: 2847050000 | D6: =C6-B6 -> 573150000 | E6: =VLOOKUP(A6,KOORDINAT!A:B,2,0) -> -6.207533 | F6: =VLOOKUP(A6,KOORDINAT!A:C,3,0) -> 106.79079 | G6: =D6/B6 -> 0.25205594 | H6: =IFS(G6 > 35%, "Sangat Baik", G6 >= 0%, "Baik", G6 >= -35%, "Kurang Baik", G6 < -35%, "Jelek") -> Baik | I6: 129
A7: KYB005 | B7: 2345850000 | C7: 2656750000 | D7: =C7-B7 -> 310900000 | E7: =VLOOKUP(A7,KOORDINAT!A:B,2,0) -> -6.217174 | F7: =VLOOKUP(A7,KOORDINAT!A:C,3,0) -> 106.8445 | G7: =D7/B7 -> 0.13253192 | H7: =IFS(G7 > 35%, "Sangat Baik", G7 >= 0%, "Baik", G7 >= -35%, "Kurang Baik", G7 < -35%, "Jelek") -> Baik | I7: 127
A8: KYB009 | B8: 2637850000 | C8: 2578500000 | D8: =C8-B8 -> -59350000 | E8: =VLOOKUP(A8,KOORDINAT!A:B,2,0) -> -6.262134 | F8: =VLOOKUP(A8,KOORDINAT!A:C,3,0) -> 106.79675 | G8: =D8/B8 -> -0.022499384 | H8: =IFS(G8 > 35%, "Sangat Baik", G8 >= 0%, "Baik", G8 >= -35%, "Kurang Baik", G8 < -35%, "Jelek") -> Kurang Baik | I8: 123
A9: DPR003 | B9: 1723450000 | C9: 2537200000 | D9: =C9-B9 -> 813750000 | E9: =VLOOKUP(A9,KOORDINAT!A:B,2,0) -> -8.694612 | F9: =VLOOKUP(A9,KOORDINAT!A:C,3,0) -> 115.21872 | G9: =D9/B9 -> 0.47216339 | H9: =IFS(G9 > 35%, "Sangat Baik", G9 >= 0%, "Baik", G9 >= -35%, "Kurang Baik", G9 < -35%, "Jelek") -> Sangat Baik | I9: 58
A10: GGP001 | B10: 1852850000 | C10: 2360150000 | D10: =C10-B10 -> 507300000 | E10: =VLOOKUP(A10,KOORDINAT!A:B,2,0) -> -6.187187 | F10: =VLOOKUP(A10,KOORDINAT!A:C,3,0) -> 106.80764 | G10: =D10/B10 -> 0.27379442 | H10: =IFS(G10 > 35%, "Sangat Baik", G10 >= 0%, "Baik", G10 >= -35%, "Kurang Baik", G10 < -35%, "Jelek") -> Baik | I10: 125
A11: CKR010 | B11: 1690800000 | C11: 2287650000 | D11: =C11-B11 -> 596850000 | E11: =VLOOKUP(A11,KOORDINAT!A:B,2,0) -> -6.378256 | F11: =VLOOKUP(A11,KOORDINAT!A:C,3,0) -> 107.11203 | G11: =D11/B11 -> 0.35299858 | H11: =IFS(G11 > 35%, "Sangat Baik", G11 >= 0%, "Baik", G11 >= -35%, "Kurang Baik", G11 < -35%, "Jelek") -> Sangat Baik | I11: 78
A12: TNA005 | B12: 1687550000 | C12: 2082100000 | D12: =C12-B12 -> 394550000 | E12: =VLOOKUP(A12,KOORDINAT!A:B,2,0) -> -6.187989 | F12: =VLOOKUP(A12,KOORDINAT!A:C,3,0) -> 106.86392 | G12: =D12/B12 -> 0.23380048 | H12: =IFS(G12 > 35%, "Sangat Baik", G12 >= 0%, "Baik", G12 >= -35%, "Kurang Baik", G12 < -35%, "Jelek") -> Baik | I12: 124
A13: DPR007 | B13: 1200500000 | C13: 1990000000 | D13: =C13-B13 -> 789500000 | E13: =VLOOKUP(A13,KOORDINAT!A:B,2,0) -> -8.681106 | F13: =VLOOKUP(A13,KOORDINAT!A:C,3,0) -> 115.20131 | G13: =D13/B13 -> 0.65764265 | H13: =IFS(G13 > 35%, "Sangat Baik", G13 >= 0%, "Baik", G13 >= -35%, "Kurang Baik", G13 < -35%, "Jelek") -> Sangat Baik | I13: 95
... A1158: TJP029 | B1158: 0 | C1158: 111800000 | D1158: =C1158-B1158 -> 111800000 | E1158: =VLOOKUP(A1158,KOORDINAT!A:B,2,0) -> -6.108197 | F1158: =VLOOKUP(A1158,KOORDINAT!A:C,3,0) -> 106.72011 | G1158: =D1158/B1158 -> #DIV/0! | H1158: =IFS(G1158 > 35%, "Sangat Baik", G1158 >= 0%, "Baik", G1158 >= -35%, "Kurang Baik", G1158 < -35%, "Jelek") -> #DIV/0! | I1158: 13

Sheet KOORDINAT
A1: nama_cabang | B1: latitude_cabang | C1: longitude_cabang
A2: PENJUALAN
A3: CKG001 | B3: -6.189655 | C3: 106.89099
A4: TNA001 | B4: -6.170378 | C4: 106.86612
A5: KYB001 | B5: -6.218429 | C5: 106.8452
A6: GGP001 | B6: -6.187187 | C6: 106.80764
A7: KYB002 | B7: -6.274773 | C7: 106.84618
A8: TJP001 | B8: -6.13006 | C8: 106.90106
A9: KYB003 | B9: -6.207533 | C9: 106.79079
A10: GGP002 | B10: -6.164994 | C10: 106.78249
A11: BKS001 | B11: -6.267963 | C11: 106.9116
A12: KYB004 | B12: -6.254488 | C12: 106.84263
A13: TNA002 | B13: -6.172233 | C13: 106.86355
A14: DPK001 | B14: -6.388311 | C14: 106.82662
... A29: GGP004 | B29: -6.152109 | C29: 106.7969
A30: CKG007
A31: KTB
A32: GGP005 | B32: -6.137781 | C32: 106.75926
A33: GGP006 | B33: -6.15357 | C33: 106.7257
A34: CKG008 | B34: -6.25761 | C34: 106.8638
A35: CKG009 | B35: -6.240151 | C35: 106.86915
A36: TNA004 | B36: -6.169646 | C36: 106.86772
A37: GGP007 | B37: -6.165685 | C37: 106.78407
A38: CKG010 | B38: -6.19601 | C38: 106.85896
A39: CKG011 | B39: -6.196607 | C39: 106.8912
A40: KYB006
A41: DPK006 | B41: -6.387814 | C41: 106.82682
A42: CKG012 | B42: -6.266678 | C42: 106.86598
A43: KYB007 | B43: -6.236131 | C43: 106.89762
A44: CKG013 | B44: -6.188145 | C44: 106.86359
A45: TNA005 | B45: -6.187989 | C45: 106.86392
A46: CKG014 | B46: -6.227623 | C46: 106.92097
A47: CKG015 | B47: -6.226897 | C47: 106.86706
A48: KYB008 | B48: -6.26265 | C48: 106.77509
A49: BKS004 | B49: -6.228729 | C49: 106.97711
A50: KYB009 | B50: -6.262134 | C50: 106.79675
A51: DPK007 | B51: -6.316363 | C51: 106.78273
A52: KYB010 | B52: -6.280497 | C52: 106.84502
... A88: BKS013 | B88: -6.210542 | C88: 106.97878
A89: TNA009
...

Sheet Sheet5
A1: cabang | B1: Omset Jan25 | C1: Omset Mei26 | D1: Growth | E1: latitude_cabang | F1: longitude_cabang | G1: Persen Growth | H1: Kategori | I1: lama_buka_bulan
A2: GGP031 | B2: 2304800000 | C2: 3322750000 | D2: 1017950000 | E2: -6.150095 | F2: 106.81736 | G2: 0.44166522 | H2: Sangat Baik | I2: 104
A3: MGW001 | B3: 1970100000 | C3: 3302900000 | D3: 1332800000 | E3: -8.741153 | F3: 115.17865 | G3: 0.67651388 | H3: Sangat Baik | I3: 104
A4: DPR001 | B4: 2672300000 | C4: 3207300000 | D4: 535000000 | E4: -8.68093 | F4: 115.20171 | G4: 0.20020207 | H4: Baik | I4: 104
A5: GGP033 | B5: 2025350000 | C5: 2862550000 | D5: 837200000 | E5: -6.16589 | F5: 106.79969 | G5: 0.41336065 | H5: Sangat Baik | I5: 105
A6: KYB003 | B6: 2273900000 | C6: 2847050000 | D6: 573150000 | E6: -6.207533 | F6: 106.79079 | G6: 0.25205594 | H6: Baik | I6: 129
A7: KYB005 | B7: 2345850000 | C7: 2656750000 | D7: 310900000 | E7: -6.217174 | F7: 106.8445 | G7: 0.13253192 | H7: Baik | I7: 127
A8: KYB009 | B8: 2637850000 | C8: 2578500000 | D8: -59350000 | E8: -6.262134 | F8: 106.79675 | G8: -0.022499384 | H8: Kurang Baik | I8: 123
A9: DPR003 | B9: 1723450000 | C9: 2537200000 | D9: 813750000 | E9: -8.694612 | F9: 115.21872 | G9: 0.47216339 | H9: Sangat Baik | I9: 58
A10: GGP001 | B10: 1852850000 | C10: 2360150000 | D10: 507300000 | E10: -6.187187 | F10: 106.80764 | G10: 0.27379442 | H10: Baik | I10: 125
A11: CKR010 | B11: 1690800000 | C11: 2287650000 | D11: 596850000 | E11: -6.378256 | F11: 107.11203 | G11: 0.35299858 | H11: Sangat Baik | I11: 78
A12: TNA005 | B12: 1687550000 | C12: 2082100000 | D12: 394550000 | E12: -6.187989 | F12: 106.86392 | G12: 0.23380048 | H12: Baik | I12: 124
A13: DPR007 | B13: 1200500000 | C13: 1990000000 | D13: 789500000 | E13: -8.681106 | F13: 115.20131 | G13: 0.65764265 | H13: Sangat Baik | I13: 95
... A38: CKG010 | B38: 1341900000 | C38: 1488450000 | D38: 146550000 | E38: -6.19601 | F38: 106.85896 | G38: 0.10921082 | H38: Baik | I38: 123
A39: CJR018 | B39: #N/A | C39: 1479800000 | D39: #N/A | E39: #N/A | F39: #N/A | G39: #N/A | H39: #N/A | I39: 15
A40: CKG018 | B40: 1371650000 | C40: 1468850000 | D40: 97200000 | E40: -6.227259 | F40: 106.8817 | G40: 0.070863558 | H40: Baik | I40: 108
A41: TGR003 | B41: 1033700000 | C41: 1467050000 | D41: 433350000 | E41: -6.254868 | F41: 106.56068 | G41: 0.41922221 | H41: Sangat Baik | I41: 88
A42: TGR008 | B42: 1433000000 | C42: 1453700000 | D42: 20700000 | E42: -6.184897 | F42: 106.45476 | G42: 0.01444522 | H42: Baik | I42: 84
A43: GGP019 | B43: 811400000 | C43: 1453000000 | D43: 641600000 | E43: -6.132578 | F43: 106.69021 | G43: 0.79073207 | H43: Sangat Baik | I43: 67
A44: GIN001 | B44: 810850000 | C44: 1452800000 | D44: 641950000 | E44: -8.545309 | F44: 115.32542 | G44: 0.79170007 | H44: Sangat Baik | I44: 40
A45: KYB001 | B45: 1451000000 | C45: 1450350000 | D45: -650000 | E45: -6.218429 | F45: 106.8452 | G45: -0.00044796692 | H45: Kurang Baik | I45: 122
A46: BKS010 | B46: 1450600000 | C46: 1442650000 | D46: -7950000 | E46: -6.265078 | F46: 106.9444 | G46: -0.0054804908 | H46: Kurang Baik | I46: 114
A47: CPT016 | B47: 1170650000 | C47: 1438750000 | D47: 268100000 | E47: -6.254726 | F47: 106.651 | G47: 0.22901807 | H47: Baik | I47: 63
A48: SBM007 | B48: 1093850000 | C48: 1435750000 | D48: 341900000 | E48: -6.911597 | F48: 106.89842 | G48: 0.31256571 | H48: Baik | I48: 60
A49: CKR009 | B49: 1005950000 | C49: 1435150000 | D49: 429200000 | E49: -6.335017 | F49: 107.12083 | G49: 0.42666136 | H49: Sangat Baik | I49: 80
A50: TJP003 | B50: 1141250000 | C50: 1433650000 | D50: 292400000 | E50: -6.112084 | F50: 106.88414 | G50: 0.2562103 | H50: Baik | I50: 119
A51: BKS001 | B51: 990400000 | C51: 1427250000 | D51: 436850000 | E51: -6.267963 | F51: 106.9116 | G51: 0.44108441 | H51: Sangat Baik | I51: 131
... A76: TJP021 | B76: 994950000 | C76: 1247450000 | D76: 252500000 | E76: -6.134198 | F76: 106.75049 | G76: 0.2537816 | H76: Baik | I76: 62
A77: MGW004 | B77: #N/A | C77: 1245250000 | D77: #N/A | E77: #N/A | F77: #N/A | G77: #N/A | H77: #N/A | I77: 15
A78: MGW002 | B78: 1094850000 | C78: 1238800000 | D78: 143950000 | E78: -8.646371 | F78: 115.17206 | G78: 0.1314792 | H78: Baik | I78: 54
A79: CKG022 | B79: 1148900000 | C79: 1235550000 | D79: 86650000 | E79: -6.218589 | F79: 106.89969 | G79: 0.075419967 | H79: Baik | I79: 102
A80: SBM019 | B80: 575000000 | C80: 1235550000 | D80: 660550000 | E80: -6.9883099 | F80: 106.54861 | G80: 1.1487826 | H80: Sangat Baik | I80: 20
A81: GGP003 | B81: 1031600000 | C81: 1234250000 | D81: 202650000 | E81: -6.133037 | F81: 106.72961 | G81: 0.19644242 | H81: Baik | I81: 128
A82: KWG003 | B82: 1237000000 | C82: 1229500000 | D82: -7500000 | E82: -6.273704 | F82: 107.27161 | G82: -0.0060630558 | H82: Kurang Baik | I82: 70
A83: GGP013 | B83: 1339950000 | C83: 1226300000 | D83: -113650000 | E83: -6.165275 | F83: 106.72493 | G83: -0.084816598 | H83: Kurang Baik | I83: 79
A84: BKS056 | B84: 1222900000 | C84: 1225600000 | D84: 2700000 | E84: -6.234236 | F84: 106.97139 | G84: 0.0022078665 | H84: Baik | I84: 35
A85: TNA002 | B85: 1184300000 | C85: 1224800000 | D85: 40500000 | E85: -6.172233 | F85: 106.86355 | G85: 0.034197416 | H85: Baik | I85: 121
A86: CMS004 | B86: 716850000 | C86: 1222450000 | D86: 505600000 | E86: -7.333372 | F86: 108.35396 | G86: 0.70530794 | H86: Sangat Baik | I86: 25
A87: BKS013 | B87: 1371900000 | C87: 1221400000 | D87: -150500000 | E87: -6.210542 | F87: 106.97878 | G87: -0.10970187 | H87: Kurang Baik | I87: 105
A88: BKS025 | B88: 1141600000 | C88: 1217300000 | D88: 75700000 | E88: -6.340297 | F88: 106.9783 | G88: 0.066310441 | H88: Baik | I88: 89
...

Sheet Copy of Sheet5
A1: cabang | B1: Omset Jan25 | C1: Omset Mei25 | D1: Growth | E1: latitude_cabang | F1: longitude_cabang | G1: Persen Growth | H1: Kategori | I1: lama_buka_bulan
A2: GGP031 | B2: 2304800000 | C2: 3322750000 | D2: 1017950000 | E2: -6.150095 | F2: 106.81736 | G2: 0.44166522 | H2: Sangat Baik | I2: 104
A3: MGW001 | B3: 1970100000 | C3: 3302900000 | D3: 1332800000 | E3: -8.741153 | F3: 115.17865 | G3: 0.67651388 | H3: Sangat Baik | I3: 104
A4: DPR001 | B4: 2672300000 | C4: 3207300000 | D4: 535000000 | E4: -8.68093 | F4: 115.20171 | G4: 0.20020207 | H4: Baik | I4: 104
A5: GGP033 | B5: 2025350000 | C5: 2862550000 | D5: 837200000 | E5: -6.16589 | F5: 106.79969 | G5: 0.41336065 | H5: Sangat Baik | I5: 105
A6: KYB003 | B6: 2273900000 | C6: 2847050000 | D6: 573150000 | E6: -6.207533 | F6: 106.79079 | G6: 0.25205594 | H6: Baik | I6: 129
A7: KYB005 | B7: 2345850000 | C7: 2656750000 | D7: 310900000 | E7: -6.217174 | F7: 106.8445 | G7: 0.13253192 | H7: Baik | I7: 127
A8: KYB009 | B8: 2637850000 | C8: 2578500000 | D8: -59350000 | E8: -6.262134 | F8: 106.79675 | G8: -0.022499384 | H8: Kurang Baik | I8: 123
A9: DPR003 | B9: 1723450000 | C9: 2537200000 | D9: 813750000 | E9: -8.694612 | F9: 115.21872 | G9: 0.47216339 | H9: Sangat Baik | I9: 58
A10: GGP001 | B10: 1852850000 | C10: 2360150000 | D10: 507300000 | E10: -6.187187 | F10: 106.80764 | G10: 0.27379442 | H10: Baik | I10: 125
A11: CKR010 | B11: 1690800000 | C11: 2287650000 | D11: 596850000 | E11: -6.378256 | F11: 107.11203 | G11: 0.35299858 | H11: Sangat Baik | I11: 78
A12: TNA005 | B12: 1687550000 | C12: 2082100000 | D12: 394550000 | E12: -6.187989 | F12: 106.86392 | G12: 0.23380048 | H12: Baik | I12: 124
A13: DPR007 | B13: 1200500000 | C13: 1990000000 | D13: 789500000 | E13: -8.681106 | F13: 115.20131 | G13: 0.65764265 | H13: Sangat Baik | I13: 95
... A38: CKG010 | B38: 1341900000 | C38: 1488450000 | D38: 146550000 | E38: -6.19601 | F38: 106.85896 | G38: 0.10921082 | H38: Baik | I38: 123
A39: CJR018 | B39: #N/A | C39: 1479800000 | D39: #N/A | E39: #N/A | F39: #N/A | G39: #N/A | H39: #N/A | I39: 15
A40: CKG018 | B40: 1371650000 | C40: 1468850000 | D40: 97200000 | E40: -6.227259 | F40: 106.8817 | G40: 0.070863558 | H40: Baik | I40: 108
A41: TGR003 | B41: 1033700000 | C41: 1467050000 | D41: 433350000 | E41: -6.254868 | F41: 106.56068 | G41: 0.41922221 | H41: Sangat Baik | I41: 88
A42: TGR008 | B42: 1433000000 | C42: 1453700000 | D42: 20700000 | E42: -6.184897 | F42: 106.45476 | G42: 0.01444522 | H42: Baik | I42: 84
A43: GGP019 | B43: 811400000 | C43: 1453000000 | D43: 641600000 | E43: -6.132578 | F43: 106.69021 | G43: 0.79073207 | H43: Sangat Baik | I43: 67
A44: GIN001 | B44: 810850000 | C44: 1452800000 | D44: 641950000 | E44: -8.545309 | F44: 115.32542 | G44: 0.79170007 | H44: Sangat Baik | I44: 40
A45: KYB001 | B45: 1451000000 | C45: 1450350000 | D45: -650000 | E45: -6.218429 | F45: 106.8452 | G45: -0.00044796692 | H45: Kurang Baik | I45: 122
A46: BKS010 | B46: 1450600000 | C46: 1442650000 | D46: -7950000 | E46: -6.265078 | F46: 106.9444 | G46: -0.0054804908 | H46: Kurang Baik | I46: 114
A47: CPT016 | B47: 1170650000 | C47: 1438750000 | D47: 268100000 | E47: -6.254726 | F47: 106.651 | G47: 0.22901807 | H47: Baik | I47: 63
A48: SBM007 | B48: 1093850000 | C48: 1435750000 | D48: 341900000 | E48: -6.911597 | F48: 106.89842 | G48: 0.31256571 | H48: Baik | I48: 60
A49: CKR009 | B49: 1005950000 | C49: 1435150000 | D49: 429200000 | E49: -6.335017 | F49: 107.12083 | G49: 0.42666136 | H49: Sangat Baik | I49: 80
A50: TJP003 | B50: 1141250000 | C50: 1433650000 | D50: 292400000 | E50: -6.112084 | F50: 106.88414 | G50: 0.2562103 | H50: Baik | I50: 119
A51: BKS001 | B51: 990400000 | C51: 1427250000 | D51: 436850000 | E51: -6.267963 | F51: 106.9116 | G51: 0.44108441 | H51: Sangat Baik | I51: 131
... A76: TJP021 | B76: 994950000 | C76: 1247450000 | D76: 252500000 | E76: -6.134198 | F76: 106.75049 | G76: 0.2537816 | H76: Baik | I76: 62
A77: MGW004 | B77: #N/A | C77: 1245250000 | D77: #N/A | E77: #N/A | F77: #N/A | G77: #N/A | H77: #N/A | I77: 15
A78: MGW002 | B78: 1094850000 | C78: 1238800000 | D78: 143950000 | E78: -8.646371 | F78: 115.17206 | G78: 0.1314792 | H78: Baik | I78: 54
A79: CKG022 | B79: 1148900000 | C79: 1235550000 | D79: 86650000 | E79: -6.218589 | F79: 106.89969 | G79: 0.075419967 | H79: Baik | I79: 102
A80: SBM019 | B80: 575000000 | C80: 1235550000 | D80: 660550000 | E80: -6.9883099 | F80: 106.54861 | G80: 1.1487826 | H80: Sangat Baik | I80: 20
A81: GGP003 | B81: 1031600000 | C81: 1234250000 | D81: 202650000 | E81: -6.133037 | F81: 106.72961 | G81: 0.19644242 | H81: Baik | I81: 128
A82: KWG003 | B82: 1237000000 | C82: 1229500000 | D82: -7500000 | E82: -6.273704 | F82: 107.27161 | G82: -0.0060630558 | H82: Kurang Baik | I82: 70
A83: GGP013 | B83: 1339950000 | C83: 1226300000 | D83: -113650000 | E83: -6.165275 | F83: 106.72493 | G83: -0.084816598 | H83: Kurang Baik | I83: 79
A84: BKS056 | B84: 1222900000 | C84: 1225600000 | D84: 2700000 | E84: -6.234236 | F84: 106.97139 | G84: 0.0022078665 | H84: Baik | I84: 35
A85: TNA002 | B85: 1184300000 | C85: 1224800000 | D85: 40500000 | E85: -6.172233 | F85: 106.86355 | G85: 0.034197416 | H85: Baik | I85: 121
A86: CMS004 | B86: 716850000 | C86: 1222450000 | D86: 505600000 | E86: -7.333372 | F86: 108.35396 | G86: 0.70530794 | H86: Sangat Baik | I86: 25
A87: BKS013 | B87: 1371900000 | C87: 1221400000 | D87: -150500000 | E87: -6.210542 | F87: 106.97878 | G87: -0.10970187 | H87: Kurang Baik | I87: 105
A88: BKS025 | B88: 1141600000 | C88: 1217300000 | D88: 75700000 | E88: -6.340297 | F88: 106.9783 | G88: 0.066310441 | H88: Baik | I88: 89
...

Sheet Copy of Summary
A1: cabang | B1: Omset Jan25 | C1: Omset Mei26 | D1: Growth | E1: latitude_cabang | F1: longitude_cabang | G1: Persen Growth | H1: lama_buka_bulan
A2: DPR001 | B2: 2672300000 | C2: 3207300000 | D2: 535000000 | E2: -8.68093 | F2: 115.20171 | G2: =D2/B2 -> 0.20020207 | H2: =VLOOKUP(A2,Sheet4!A:B,2,0) -> 104
A3: KYB009 | B3: 2637850000 | C3: 2578500000 | D3: -59350000 | E3: -6.262134 | F3: 106.79675 | G3: =D3/B3 -> -0.022499384 | H3: =VLOOKUP(A3,Sheet4!A:B,2,0) -> 123
A4: KYB005 | B4: 2345850000 | C4: 2656750000 | D4: 310900000 | E4: -6.217174 | F4: 106.8445 | G4: =D4/B4 -> 0.13253192 | H4: =VLOOKUP(A4,Sheet4!A:B,2,0) -> 127
A5: GGP031 | B5: 2304800000 | C5: 3322750000 | D5: 1017950000 | E5: -6.150095 | F5: 106.81736 | G5: =D5/B5 -> 0.44166522 | H5: =VLOOKUP(A5,Sheet4!A:B,2,0) -> 104
A6: KYB003 | B6: 2273900000 | C6: 2847050000 | D6: 573150000 | E6: -6.207533 | F6: 106.79079 | G6: =D6/B6 -> 0.25205594 | H6: =VLOOKUP(A6,Sheet4!A:B,2,0) -> 129
A7: GGP033 | B7: 2025350000 | C7: 2862550000 | D7: 837200000 | E7: -6.16589 | F7: 106.79969 | G7: =D7/B7 -> 0.41336065 | H7: =VLOOKUP(A7,Sheet4!A:B,2,0) -> 105
A8: MGW001 | B8: 1970100000 | C8: 3302900000 | D8: 1332800000 | E8: -8.741153 | F8: 115.17865 | G8: =D8/B8 -> 0.67651388 | H8: =VLOOKUP(A8,Sheet4!A:B,2,0) -> 104
A9: GGP001 | B9: 1852850000 | C9: 2360150000 | D9: 507300000 | E9: -6.187187 | F9: 106.80764 | G9: =D9/B9 -> 0.27379442 | H9: =VLOOKUP(A9,Sheet4!A:B,2,0) -> 125
A10: DPR003 | B10: 1723450000 | C10: 2537200000 | D10: 813750000 | E10: -8.694612 | F10: 115.21872 | G10: =D10/B10 -> 0.47216339 | H10: =VLOOKUP(A10,Sheet4!A:B,2,0) -> 58
A11: TNG025 | B11: 1721500000 | C11: 1782950000 | D11: 61450000 | E11: -6.207352 | F11: 106.60545 | G11: =D11/B11 -> 0.035695614 | H11: =VLOOKUP(A11,Sheet4!A:B,2,0) -> 104
A12: DPK004 | B12: 1718300000 | C12: 1635800000 | D12: -82500000 | E12: -6.354991 | F12: 106.84318 | G12: =D12/B12 -> -0.048012571 | H12: =VLOOKUP(A12,Sheet4!A:B,2,0) -> 127
A13: CKR010 | B13: 1690800000 | C13: 2287650000 | D13: 596850000 | E13: -6.378256 | F13: 107.11203 | G13: =D13/B13 -> 0.35299858 | H13: =VLOOKUP(A13,Sheet4!A:B,2,0) -> 78
... A1071: DPK053 | B1071: 1350000 | C1071: 176950000 | D1071: 175600000 | E1071: -6.4065532 | F1071: 106.78933 | G1071: =D1071/B1071 -> 130.07407 | H1071: =VLOOKUP(A1071,Sheet4!A:B,2,0) -> 16

Sheet Sheet4
A1: cabang | B1: lama_buka_bulan
A2: GGP031 | B2: 104
A3: MGW001 | B3: 104
A4: DPR001 | B4: 104
A5: GGP033 | B5: 105
A6: KYB003 | B6: 129
A7: KYB005 | B7: 127
A8: KYB009 | B8: 123
A9: DPR003 | B9: 58
A10: GGP001 | B10: 125
A11: CKR010 | B11: 78
A12: TNA005 | B12: 124
A13: DPR007 | B13: 95
... A1662: UNR009 | B1662: 0
